{
 "cells": [
  {
   "cell_type": "code",
   "execution_count": 2,
   "id": "05643599",
   "metadata": {},
   "outputs": [],
   "source": [
    "import tensorflow as tf\n",
    "from tensorflow.keras.utils import image_dataset_from_directory"
   ]
  },
  {
   "cell_type": "code",
   "execution_count": 4,
   "id": "fdcddab8",
   "metadata": {},
   "outputs": [
    {
     "ename": "OSError",
     "evalue": "No file or directory found at itelli1",
     "output_type": "error",
     "traceback": [
      "\u001b[1;31m---------------------------------------------------------------------------\u001b[0m",
      "\u001b[1;31mOSError\u001b[0m                                   Traceback (most recent call last)",
      "\u001b[1;32m<ipython-input-4-d55ca58c0f3f>\u001b[0m in \u001b[0;36m<module>\u001b[1;34m\u001b[0m\n\u001b[1;32m----> 1\u001b[1;33m \u001b[0mmodel\u001b[0m \u001b[1;33m=\u001b[0m \u001b[0mtf\u001b[0m\u001b[1;33m.\u001b[0m\u001b[0mkeras\u001b[0m\u001b[1;33m.\u001b[0m\u001b[0mmodels\u001b[0m\u001b[1;33m.\u001b[0m\u001b[0mload_model\u001b[0m\u001b[1;33m(\u001b[0m\u001b[1;34m'itelli1'\u001b[0m\u001b[1;33m)\u001b[0m\u001b[1;33m\u001b[0m\u001b[1;33m\u001b[0m\u001b[0m\n\u001b[0m",
      "\u001b[1;32mD:\\anaconda\\lib\\site-packages\\keras\\utils\\traceback_utils.py\u001b[0m in \u001b[0;36merror_handler\u001b[1;34m(*args, **kwargs)\u001b[0m\n\u001b[0;32m     65\u001b[0m     \u001b[1;32mexcept\u001b[0m \u001b[0mException\u001b[0m \u001b[1;32mas\u001b[0m \u001b[0me\u001b[0m\u001b[1;33m:\u001b[0m  \u001b[1;31m# pylint: disable=broad-except\u001b[0m\u001b[1;33m\u001b[0m\u001b[1;33m\u001b[0m\u001b[0m\n\u001b[0;32m     66\u001b[0m       \u001b[0mfiltered_tb\u001b[0m \u001b[1;33m=\u001b[0m \u001b[0m_process_traceback_frames\u001b[0m\u001b[1;33m(\u001b[0m\u001b[0me\u001b[0m\u001b[1;33m.\u001b[0m\u001b[0m__traceback__\u001b[0m\u001b[1;33m)\u001b[0m\u001b[1;33m\u001b[0m\u001b[1;33m\u001b[0m\u001b[0m\n\u001b[1;32m---> 67\u001b[1;33m       \u001b[1;32mraise\u001b[0m \u001b[0me\u001b[0m\u001b[1;33m.\u001b[0m\u001b[0mwith_traceback\u001b[0m\u001b[1;33m(\u001b[0m\u001b[0mfiltered_tb\u001b[0m\u001b[1;33m)\u001b[0m \u001b[1;32mfrom\u001b[0m \u001b[1;32mNone\u001b[0m\u001b[1;33m\u001b[0m\u001b[1;33m\u001b[0m\u001b[0m\n\u001b[0m\u001b[0;32m     68\u001b[0m     \u001b[1;32mfinally\u001b[0m\u001b[1;33m:\u001b[0m\u001b[1;33m\u001b[0m\u001b[1;33m\u001b[0m\u001b[0m\n\u001b[0;32m     69\u001b[0m       \u001b[1;32mdel\u001b[0m \u001b[0mfiltered_tb\u001b[0m\u001b[1;33m\u001b[0m\u001b[1;33m\u001b[0m\u001b[0m\n",
      "\u001b[1;32mD:\\anaconda\\lib\\site-packages\\keras\\saving\\save.py\u001b[0m in \u001b[0;36mload_model\u001b[1;34m(filepath, custom_objects, compile, options)\u001b[0m\n\u001b[0;32m    207\u001b[0m         \u001b[1;32mif\u001b[0m \u001b[0misinstance\u001b[0m\u001b[1;33m(\u001b[0m\u001b[0mfilepath\u001b[0m\u001b[1;33m,\u001b[0m \u001b[0mstr\u001b[0m\u001b[1;33m)\u001b[0m\u001b[1;33m:\u001b[0m\u001b[1;33m\u001b[0m\u001b[1;33m\u001b[0m\u001b[0m\n\u001b[0;32m    208\u001b[0m           \u001b[1;32mif\u001b[0m \u001b[1;32mnot\u001b[0m \u001b[0mtf\u001b[0m\u001b[1;33m.\u001b[0m\u001b[0mio\u001b[0m\u001b[1;33m.\u001b[0m\u001b[0mgfile\u001b[0m\u001b[1;33m.\u001b[0m\u001b[0mexists\u001b[0m\u001b[1;33m(\u001b[0m\u001b[0mfilepath\u001b[0m\u001b[1;33m)\u001b[0m\u001b[1;33m:\u001b[0m\u001b[1;33m\u001b[0m\u001b[1;33m\u001b[0m\u001b[0m\n\u001b[1;32m--> 209\u001b[1;33m             \u001b[1;32mraise\u001b[0m \u001b[0mIOError\u001b[0m\u001b[1;33m(\u001b[0m\u001b[1;34mf'No file or directory found at {filepath}'\u001b[0m\u001b[1;33m)\u001b[0m\u001b[1;33m\u001b[0m\u001b[1;33m\u001b[0m\u001b[0m\n\u001b[0m\u001b[0;32m    210\u001b[0m           \u001b[1;32mif\u001b[0m \u001b[0msaving_utils\u001b[0m\u001b[1;33m.\u001b[0m\u001b[0mis_hdf5_filepath\u001b[0m\u001b[1;33m(\u001b[0m\u001b[0mfilepath\u001b[0m\u001b[1;33m)\u001b[0m \u001b[1;32mand\u001b[0m \u001b[0mh5py\u001b[0m \u001b[1;32mis\u001b[0m \u001b[1;32mNone\u001b[0m\u001b[1;33m:\u001b[0m\u001b[1;33m\u001b[0m\u001b[1;33m\u001b[0m\u001b[0m\n\u001b[0;32m    211\u001b[0m             raise ImportError(\n",
      "\u001b[1;31mOSError\u001b[0m: No file or directory found at itelli1"
     ]
    }
   ],
   "source": [
    "model = tf.keras.models.load_model(projects/intelligence Gathering/intelli1.h5)"
   ]
  },
  {
   "cell_type": "code",
   "execution_count": null,
   "id": "3c663d14",
   "metadata": {},
   "outputs": [],
   "source": []
  }
 ],
 "metadata": {
  "kernelspec": {
   "display_name": "Python 3",
   "language": "python",
   "name": "python3"
  },
  "language_info": {
   "codemirror_mode": {
    "name": "ipython",
    "version": 3
   },
   "file_extension": ".py",
   "mimetype": "text/x-python",
   "name": "python",
   "nbconvert_exporter": "python",
   "pygments_lexer": "ipython3",
   "version": "3.8.8"
  }
 },
 "nbformat": 4,
 "nbformat_minor": 5
}
